[2024-12-24T12:02:05.172+0000] {taskinstance.py:1956} INFO - Dependencies all met for dep_context=non-requeueable deps ti=<TaskInstance: weather_dag.transform_data_all_files scheduled__2024-12-24T12:01:00+00:00 [queued]>
[2024-12-24T12:02:05.180+0000] {taskinstance.py:1956} INFO - Dependencies all met for dep_context=requeueable deps ti=<TaskInstance: weather_dag.transform_data_all_files scheduled__2024-12-24T12:01:00+00:00 [queued]>
[2024-12-24T12:02:05.180+0000] {taskinstance.py:2170} INFO - Starting attempt 1 of 3
[2024-12-24T12:02:05.191+0000] {taskinstance.py:2191} INFO - Executing <Task(PythonOperator): transform_data_all_files> on 2024-12-24 12:01:00+00:00
[2024-12-24T12:02:05.198+0000] {standard_task_runner.py:60} INFO - Started process 7143 to run task
[2024-12-24T12:02:05.201+0000] {standard_task_runner.py:87} INFO - Running: ['***', 'tasks', 'run', 'weather_dag', 'transform_data_all_files', 'scheduled__2024-12-24T12:01:00+00:00', '--job-id', '1513', '--raw', '--subdir', 'DAGS_FOLDER/extract.py', '--cfg-path', '/tmp/tmpg3q_vq95']
[2024-12-24T12:02:05.202+0000] {standard_task_runner.py:88} INFO - Job 1513: Subtask transform_data_all_files
[2024-12-24T12:02:05.212+0000] {warnings.py:109} WARNING - /home/***/.local/lib/python3.8/site-packages/***/settings.py:194: DeprecationWarning: The sql_alchemy_conn option in [core] has been moved to the sql_alchemy_conn option in [database] - the old setting has been used, but please update your config.
  SQL_ALCHEMY_CONN = conf.get("database", "SQL_ALCHEMY_CONN")

[2024-12-24T12:02:05.242+0000] {task_command.py:423} INFO - Running <TaskInstance: weather_dag.transform_data_all_files scheduled__2024-12-24T12:01:00+00:00 [running]> on host f70f31c57d74
[2024-12-24T12:02:05.328+0000] {taskinstance.py:2480} INFO - Exporting env vars: AIRFLOW_CTX_DAG_EMAIL='thiernosidybah232@gmail.com' AIRFLOW_CTX_DAG_OWNER='***' AIRFLOW_CTX_DAG_ID='weather_dag' AIRFLOW_CTX_TASK_ID='transform_data_all_files' AIRFLOW_CTX_EXECUTION_DATE='2024-12-24T12:01:00+00:00' AIRFLOW_CTX_TRY_NUMBER='1' AIRFLOW_CTX_DAG_RUN_ID='scheduled__2024-12-24T12:01:00+00:00'
[2024-12-24T12:02:05.330+0000] {taskinstance.py:2698} ERROR - Task failed with exception
Traceback (most recent call last):
  File "/home/airflow/.local/lib/python3.8/site-packages/airflow/models/taskinstance.py", line 433, in _execute_task
    result = execute_callable(context=context, **execute_callable_kwargs)
  File "/home/airflow/.local/lib/python3.8/site-packages/airflow/operators/python.py", line 199, in execute
    return_value = self.execute_callable()
  File "/home/airflow/.local/lib/python3.8/site-packages/airflow/operators/python.py", line 216, in execute_callable
    return self.python_callable(*self.op_args, **self.op_kwargs)
  File "/opt/airflow/dags/extract.py", line 89, in test_function
    n_files = kwargs["n_files"]
KeyError: 'n_files'
[2024-12-24T12:02:05.337+0000] {taskinstance.py:1138} INFO - Marking task as UP_FOR_RETRY. dag_id=weather_dag, task_id=transform_data_all_files, execution_date=20241224T120100, start_date=20241224T120205, end_date=20241224T120205
[2024-12-24T12:02:05.350+0000] {standard_task_runner.py:107} ERROR - Failed to execute job 1513 for task transform_data_all_files ('n_files'; 7143)
[2024-12-24T12:02:05.372+0000] {local_task_job_runner.py:234} INFO - Task exited with return code 1
[2024-12-24T12:02:05.409+0000] {taskinstance.py:3280} INFO - 0 downstream tasks scheduled from follow-on schedule check
