[2024-12-24T10:55:03.788+0000] {taskinstance.py:1956} INFO - Dependencies all met for dep_context=non-requeueable deps ti=<TaskInstance: weather_dag.Is_weather_api_ready scheduled__2024-12-24T10:53:00+00:00 [queued]>
[2024-12-24T10:55:03.798+0000] {taskinstance.py:1956} INFO - Dependencies all met for dep_context=requeueable deps ti=<TaskInstance: weather_dag.Is_weather_api_ready scheduled__2024-12-24T10:53:00+00:00 [queued]>
[2024-12-24T10:55:03.798+0000] {taskinstance.py:2170} INFO - Starting attempt 2 of 3
[2024-12-24T10:55:03.810+0000] {taskinstance.py:2191} INFO - Executing <Task(HttpSensor): Is_weather_api_ready> on 2024-12-24 10:53:00+00:00
[2024-12-24T10:55:03.817+0000] {standard_task_runner.py:60} INFO - Started process 4477 to run task
[2024-12-24T10:55:03.821+0000] {standard_task_runner.py:87} INFO - Running: ['***', 'tasks', 'run', 'weather_dag', 'Is_weather_api_ready', 'scheduled__2024-12-24T10:53:00+00:00', '--job-id', '1199', '--raw', '--subdir', 'DAGS_FOLDER/extract.py', '--cfg-path', '/tmp/tmpqxqp6zs2']
[2024-12-24T10:55:03.822+0000] {standard_task_runner.py:88} INFO - Job 1199: Subtask Is_weather_api_ready
[2024-12-24T10:55:03.835+0000] {warnings.py:109} WARNING - /home/***/.local/lib/python3.8/site-packages/***/settings.py:194: DeprecationWarning: The sql_alchemy_conn option in [core] has been moved to the sql_alchemy_conn option in [database] - the old setting has been used, but please update your config.
  SQL_ALCHEMY_CONN = conf.get("database", "SQL_ALCHEMY_CONN")

[2024-12-24T10:55:03.876+0000] {task_command.py:423} INFO - Running <TaskInstance: weather_dag.Is_weather_api_ready scheduled__2024-12-24T10:53:00+00:00 [running]> on host b853fb0270cd
[2024-12-24T10:55:03.962+0000] {taskinstance.py:2480} INFO - Exporting env vars: AIRFLOW_CTX_DAG_EMAIL='thiernosidybah232@gmail.com' AIRFLOW_CTX_DAG_OWNER='***' AIRFLOW_CTX_DAG_ID='weather_dag' AIRFLOW_CTX_TASK_ID='Is_weather_api_ready' AIRFLOW_CTX_EXECUTION_DATE='2024-12-24T10:53:00+00:00' AIRFLOW_CTX_TRY_NUMBER='2' AIRFLOW_CTX_DAG_RUN_ID='scheduled__2024-12-24T10:53:00+00:00'
[2024-12-24T10:55:03.964+0000] {http.py:130} INFO - Poking: /data/2.5/weather?q=Nantes&appid=92a2228961d1701676a43daabb355f4d
[2024-12-24T10:55:03.982+0000] {taskinstance.py:2698} ERROR - Task failed with exception
Traceback (most recent call last):
  File "/home/airflow/.local/lib/python3.8/site-packages/airflow/models/taskinstance.py", line 433, in _execute_task
    result = execute_callable(context=context, **execute_callable_kwargs)
  File "/home/airflow/.local/lib/python3.8/site-packages/airflow/sensors/base.py", line 265, in execute
    raise e
  File "/home/airflow/.local/lib/python3.8/site-packages/airflow/sensors/base.py", line 247, in execute
    poke_return = self.poke(context)
  File "/home/airflow/.local/lib/python3.8/site-packages/airflow/providers/http/sensors/http.py", line 148, in poke
    raise exc
  File "/home/airflow/.local/lib/python3.8/site-packages/airflow/providers/http/sensors/http.py", line 132, in poke
    response = hook.run(
  File "/home/airflow/.local/lib/python3.8/site-packages/airflow/providers/http/hooks/http.py", line 145, in run
    session = self.get_conn(headers)
  File "/home/airflow/.local/lib/python3.8/site-packages/airflow/providers/http/hooks/http.py", line 98, in get_conn
    conn = self.get_connection(self.http_conn_id)
  File "/home/airflow/.local/lib/python3.8/site-packages/airflow/hooks/base.py", line 82, in get_connection
    conn = Connection.get_connection_from_secrets(conn_id)
  File "/home/airflow/.local/lib/python3.8/site-packages/airflow/models/connection.py", line 479, in get_connection_from_secrets
    raise AirflowNotFoundException(f"The conn_id `{conn_id}` isn't defined")
airflow.exceptions.AirflowNotFoundException: The conn_id `weathermap_api` isn't defined
[2024-12-24T10:55:03.985+0000] {taskinstance.py:1138} INFO - Marking task as UP_FOR_RETRY. dag_id=weather_dag, task_id=Is_weather_api_ready, execution_date=20241224T105300, start_date=20241224T105503, end_date=20241224T105503
[2024-12-24T10:55:03.995+0000] {standard_task_runner.py:107} ERROR - Failed to execute job 1199 for task Is_weather_api_ready (The conn_id `weathermap_api` isn't defined; 4477)
[2024-12-24T10:55:04.033+0000] {local_task_job_runner.py:234} INFO - Task exited with return code 1
[2024-12-24T10:55:04.064+0000] {taskinstance.py:3280} INFO - 0 downstream tasks scheduled from follow-on schedule check
