[2024-12-24T12:05:11.928+0000] {taskinstance.py:1956} INFO - Dependencies all met for dep_context=non-requeueable deps ti=<TaskInstance: weather_dag.Best_model scheduled__2024-12-24T12:03:00+00:00 [queued]>
[2024-12-24T12:05:11.938+0000] {taskinstance.py:1956} INFO - Dependencies all met for dep_context=requeueable deps ti=<TaskInstance: weather_dag.Best_model scheduled__2024-12-24T12:03:00+00:00 [queued]>
[2024-12-24T12:05:11.938+0000] {taskinstance.py:2170} INFO - Starting attempt 1 of 3
[2024-12-24T12:05:11.949+0000] {taskinstance.py:2191} INFO - Executing <Task(PythonOperator): Best_model> on 2024-12-24 12:03:00+00:00
[2024-12-24T12:05:11.961+0000] {standard_task_runner.py:60} INFO - Started process 8061 to run task
[2024-12-24T12:05:11.964+0000] {standard_task_runner.py:87} INFO - Running: ['***', 'tasks', 'run', 'weather_dag', 'Best_model', 'scheduled__2024-12-24T12:03:00+00:00', '--job-id', '1541', '--raw', '--subdir', 'DAGS_FOLDER/extract.py', '--cfg-path', '/tmp/tmpgc2qez96']
[2024-12-24T12:05:11.965+0000] {standard_task_runner.py:88} INFO - Job 1541: Subtask Best_model
[2024-12-24T12:05:11.978+0000] {warnings.py:109} WARNING - /home/***/.local/lib/python3.8/site-packages/***/settings.py:194: DeprecationWarning: The sql_alchemy_conn option in [core] has been moved to the sql_alchemy_conn option in [database] - the old setting has been used, but please update your config.
  SQL_ALCHEMY_CONN = conf.get("database", "SQL_ALCHEMY_CONN")

[2024-12-24T12:05:12.139+0000] {task_command.py:423} INFO - Running <TaskInstance: weather_dag.Best_model scheduled__2024-12-24T12:03:00+00:00 [running]> on host f70f31c57d74
[2024-12-24T12:05:12.235+0000] {taskinstance.py:2480} INFO - Exporting env vars: AIRFLOW_CTX_DAG_EMAIL='thiernosidybah232@gmail.com' AIRFLOW_CTX_DAG_OWNER='***' AIRFLOW_CTX_DAG_ID='weather_dag' AIRFLOW_CTX_TASK_ID='Best_model' AIRFLOW_CTX_EXECUTION_DATE='2024-12-24T12:03:00+00:00' AIRFLOW_CTX_TRY_NUMBER='1' AIRFLOW_CTX_DAG_RUN_ID='scheduled__2024-12-24T12:03:00+00:00'
[2024-12-24T12:05:12.282+0000] {taskinstance.py:2698} ERROR - Task failed with exception
Traceback (most recent call last):
  File "/home/airflow/.local/lib/python3.8/site-packages/airflow/models/taskinstance.py", line 433, in _execute_task
    result = execute_callable(context=context, **execute_callable_kwargs)
  File "/home/airflow/.local/lib/python3.8/site-packages/airflow/operators/python.py", line 199, in execute
    return_value = self.execute_callable()
  File "/home/airflow/.local/lib/python3.8/site-packages/airflow/operators/python.py", line 216, in execute_callable
    return self.python_callable(*self.op_args, **self.op_kwargs)
  File "/opt/airflow/dags/extract.py", line 260, in best_model_function
    data, score_lr, score_random_forest, score_decision_tree = task_instance.xcom_pull(task_ids = ["preprocessing_data", "linear_regression", "Random_Forest", "Decision_tree_regressor"])
ValueError: not enough values to unpack (expected 4, got 3)
[2024-12-24T12:05:12.287+0000] {taskinstance.py:1138} INFO - Marking task as UP_FOR_RETRY. dag_id=weather_dag, task_id=Best_model, execution_date=20241224T120300, start_date=20241224T120511, end_date=20241224T120512
[2024-12-24T12:05:12.338+0000] {standard_task_runner.py:107} ERROR - Failed to execute job 1541 for task Best_model (not enough values to unpack (expected 4, got 3); 8061)
[2024-12-24T12:05:12.378+0000] {local_task_job_runner.py:234} INFO - Task exited with return code 1
[2024-12-24T12:05:12.407+0000] {taskinstance.py:3280} INFO - 0 downstream tasks scheduled from follow-on schedule check
