[2024-12-23T16:43:41.092+0000] {taskinstance.py:1956} INFO - Dependencies all met for dep_context=non-requeueable deps ti=<TaskInstance: weather_dag.Extract_weather_data scheduled__2024-12-23T14:58:00+00:00 [queued]>
[2024-12-23T16:43:41.098+0000] {taskinstance.py:1956} INFO - Dependencies all met for dep_context=requeueable deps ti=<TaskInstance: weather_dag.Extract_weather_data scheduled__2024-12-23T14:58:00+00:00 [queued]>
[2024-12-23T16:43:41.098+0000] {taskinstance.py:2170} INFO - Starting attempt 1 of 3
[2024-12-23T16:43:41.108+0000] {taskinstance.py:2191} INFO - Executing <Task(PythonOperator): Extract_weather_data> on 2024-12-23 14:58:00+00:00
[2024-12-23T16:43:41.117+0000] {standard_task_runner.py:60} INFO - Started process 131 to run task
[2024-12-23T16:43:41.121+0000] {standard_task_runner.py:87} INFO - Running: ['***', 'tasks', 'run', 'weather_dag', 'Extract_weather_data', 'scheduled__2024-12-23T14:58:00+00:00', '--job-id', '679', '--raw', '--subdir', 'DAGS_FOLDER/extract.py', '--cfg-path', '/tmp/tmp4cnj5d3s']
[2024-12-23T16:43:41.122+0000] {standard_task_runner.py:88} INFO - Job 679: Subtask Extract_weather_data
[2024-12-23T16:43:41.134+0000] {warnings.py:109} WARNING - /home/***/.local/lib/python3.8/site-packages/***/settings.py:194: DeprecationWarning: The sql_alchemy_conn option in [core] has been moved to the sql_alchemy_conn option in [database] - the old setting has been used, but please update your config.
  SQL_ALCHEMY_CONN = conf.get("database", "SQL_ALCHEMY_CONN")

[2024-12-23T16:43:41.175+0000] {task_command.py:423} INFO - Running <TaskInstance: weather_dag.Extract_weather_data scheduled__2024-12-23T14:58:00+00:00 [running]> on host b853fb0270cd
[2024-12-23T16:43:41.256+0000] {taskinstance.py:2480} INFO - Exporting env vars: AIRFLOW_CTX_DAG_EMAIL='thiernosidybah232@gmail.com' AIRFLOW_CTX_DAG_OWNER='***' AIRFLOW_CTX_DAG_ID='weather_dag' AIRFLOW_CTX_TASK_ID='Extract_weather_data' AIRFLOW_CTX_EXECUTION_DATE='2024-12-23T14:58:00+00:00' AIRFLOW_CTX_TRY_NUMBER='1' AIRFLOW_CTX_DAG_RUN_ID='scheduled__2024-12-23T14:58:00+00:00'
[2024-12-23T16:43:41.265+0000] {taskinstance.py:2698} ERROR - Task failed with exception
Traceback (most recent call last):
  File "/home/airflow/.local/lib/python3.8/site-packages/urllib3/connection.py", line 174, in _new_conn
    conn = connection.create_connection(
  File "/home/airflow/.local/lib/python3.8/site-packages/urllib3/util/connection.py", line 72, in create_connection
    for res in socket.getaddrinfo(host, port, family, socket.SOCK_STREAM):
  File "/usr/local/lib/python3.8/socket.py", line 918, in getaddrinfo
    for res in _socket.getaddrinfo(host, port, family, type, proto, flags):
socket.gaierror: [Errno -3] Temporary failure in name resolution

During handling of the above exception, another exception occurred:

Traceback (most recent call last):
  File "/home/airflow/.local/lib/python3.8/site-packages/urllib3/connectionpool.py", line 715, in urlopen
    httplib_response = self._make_request(
  File "/home/airflow/.local/lib/python3.8/site-packages/urllib3/connectionpool.py", line 404, in _make_request
    self._validate_conn(conn)
  File "/home/airflow/.local/lib/python3.8/site-packages/urllib3/connectionpool.py", line 1058, in _validate_conn
    conn.connect()
  File "/home/airflow/.local/lib/python3.8/site-packages/urllib3/connection.py", line 363, in connect
    self.sock = conn = self._new_conn()
  File "/home/airflow/.local/lib/python3.8/site-packages/urllib3/connection.py", line 186, in _new_conn
    raise NewConnectionError(
urllib3.exceptions.NewConnectionError: <urllib3.connection.HTTPSConnection object at 0x7fcdc8ab3640>: Failed to establish a new connection: [Errno -3] Temporary failure in name resolution

During handling of the above exception, another exception occurred:

Traceback (most recent call last):
  File "/home/airflow/.local/lib/python3.8/site-packages/requests/adapters.py", line 486, in send
    resp = conn.urlopen(
  File "/home/airflow/.local/lib/python3.8/site-packages/urllib3/connectionpool.py", line 799, in urlopen
    retries = retries.increment(
  File "/home/airflow/.local/lib/python3.8/site-packages/urllib3/util/retry.py", line 592, in increment
    raise MaxRetryError(_pool, url, error or ResponseError(cause))
urllib3.exceptions.MaxRetryError: HTTPSConnectionPool(host='api.openweathermap.org', port=443): Max retries exceeded with url: /data/2.5/weather?q=Toulouse&appid=92a2228961d1701676a43daabb355f4d (Caused by NewConnectionError('<urllib3.connection.HTTPSConnection object at 0x7fcdc8ab3640>: Failed to establish a new connection: [Errno -3] Temporary failure in name resolution'))

During handling of the above exception, another exception occurred:

Traceback (most recent call last):
  File "/home/airflow/.local/lib/python3.8/site-packages/airflow/models/taskinstance.py", line 433, in _execute_task
    result = execute_callable(context=context, **execute_callable_kwargs)
  File "/home/airflow/.local/lib/python3.8/site-packages/airflow/operators/python.py", line 199, in execute
    return_value = self.execute_callable()
  File "/home/airflow/.local/lib/python3.8/site-packages/airflow/operators/python.py", line 216, in execute_callable
    return self.python_callable(*self.op_args, **self.op_kwargs)
  File "/opt/airflow/dags/extract.py", line 36, in extract_data
    response = requests.get(url)
  File "/home/airflow/.local/lib/python3.8/site-packages/requests/api.py", line 73, in get
    return request("get", url, params=params, **kwargs)
  File "/home/airflow/.local/lib/python3.8/site-packages/requests/api.py", line 59, in request
    return session.request(method=method, url=url, **kwargs)
  File "/home/airflow/.local/lib/python3.8/site-packages/requests/sessions.py", line 589, in request
    resp = self.send(prep, **send_kwargs)
  File "/home/airflow/.local/lib/python3.8/site-packages/requests/sessions.py", line 703, in send
    r = adapter.send(request, **kwargs)
  File "/home/airflow/.local/lib/python3.8/site-packages/requests/adapters.py", line 519, in send
    raise ConnectionError(e, request=request)
requests.exceptions.ConnectionError: HTTPSConnectionPool(host='api.openweathermap.org', port=443): Max retries exceeded with url: /data/2.5/weather?q=Toulouse&appid=92a2228961d1701676a43daabb355f4d (Caused by NewConnectionError('<urllib3.connection.HTTPSConnection object at 0x7fcdc8ab3640>: Failed to establish a new connection: [Errno -3] Temporary failure in name resolution'))
[2024-12-23T16:43:41.277+0000] {taskinstance.py:1138} INFO - Marking task as UP_FOR_RETRY. dag_id=weather_dag, task_id=Extract_weather_data, execution_date=20241223T145800, start_date=20241223T164341, end_date=20241223T164341
[2024-12-23T16:43:41.289+0000] {standard_task_runner.py:107} ERROR - Failed to execute job 679 for task Extract_weather_data (HTTPSConnectionPool(host='api.openweathermap.org', port=443): Max retries exceeded with url: /data/2.5/weather?q=Toulouse&appid=92a2228961d1701676a43daabb355f4d (Caused by NewConnectionError('<urllib3.connection.HTTPSConnection object at 0x7fcdc8ab3640>: Failed to establish a new connection: [Errno -3] Temporary failure in name resolution')); 131)
[2024-12-23T16:43:41.333+0000] {local_task_job_runner.py:234} INFO - Task exited with return code 1
[2024-12-23T16:43:41.369+0000] {taskinstance.py:3280} INFO - 0 downstream tasks scheduled from follow-on schedule check
