[2024-12-17T18:43:50.863+0000] {taskinstance.py:1956} INFO - Dependencies all met for dep_context=non-requeueable deps ti=<TaskInstance: weather_dag.transform_data manual__2024-12-17T18:42:45.093711+00:00 [queued]>
[2024-12-17T18:43:50.867+0000] {taskinstance.py:1956} INFO - Dependencies all met for dep_context=requeueable deps ti=<TaskInstance: weather_dag.transform_data manual__2024-12-17T18:42:45.093711+00:00 [queued]>
[2024-12-17T18:43:50.868+0000] {taskinstance.py:2170} INFO - Starting attempt 2 of 3
[2024-12-17T18:43:50.874+0000] {taskinstance.py:2191} INFO - Executing <Task(PythonOperator): transform_data> on 2024-12-17 18:42:45.093711+00:00
[2024-12-17T18:43:50.879+0000] {standard_task_runner.py:60} INFO - Started process 14076 to run task
[2024-12-17T18:43:50.882+0000] {standard_task_runner.py:87} INFO - Running: ['***', 'tasks', 'run', 'weather_dag', 'transform_data', 'manual__2024-12-17T18:42:45.093711+00:00', '--job-id', '97', '--raw', '--subdir', 'DAGS_FOLDER/extract.py', '--cfg-path', '/tmp/tmpf_n598w0']
[2024-12-17T18:43:50.883+0000] {standard_task_runner.py:88} INFO - Job 97: Subtask transform_data
[2024-12-17T18:43:50.894+0000] {warnings.py:109} WARNING - /home/***/.local/lib/python3.8/site-packages/***/settings.py:194: DeprecationWarning: The sql_alchemy_conn option in [core] has been moved to the sql_alchemy_conn option in [database] - the old setting has been used, but please update your config.
  SQL_ALCHEMY_CONN = conf.get("database", "SQL_ALCHEMY_CONN")

[2024-12-17T18:43:50.916+0000] {task_command.py:423} INFO - Running <TaskInstance: weather_dag.transform_data manual__2024-12-17T18:42:45.093711+00:00 [running]> on host 3b537f09ccb4
[2024-12-17T18:43:50.965+0000] {taskinstance.py:2480} INFO - Exporting env vars: AIRFLOW_CTX_DAG_EMAIL='thiernosidybah232@gmail.com' AIRFLOW_CTX_DAG_OWNER='***' AIRFLOW_CTX_DAG_ID='weather_dag' AIRFLOW_CTX_TASK_ID='transform_data' AIRFLOW_CTX_EXECUTION_DATE='2024-12-17T18:42:45.093711+00:00' AIRFLOW_CTX_TRY_NUMBER='2' AIRFLOW_CTX_DAG_RUN_ID='manual__2024-12-17T18:42:45.093711+00:00'
[2024-12-17T18:43:50.966+0000] {taskinstance.py:2698} ERROR - Task failed with exception
Traceback (most recent call last):
  File "/home/airflow/.local/lib/python3.8/site-packages/airflow/models/taskinstance.py", line 433, in _execute_task
    result = execute_callable(context=context, **execute_callable_kwargs)
  File "/home/airflow/.local/lib/python3.8/site-packages/airflow/operators/python.py", line 199, in execute
    return_value = self.execute_callable()
  File "/home/airflow/.local/lib/python3.8/site-packages/airflow/operators/python.py", line 216, in execute_callable
    return self.python_callable(*self.op_args, **self.op_kwargs)
  File "/opt/airflow/dags/extract.py", line 60, in transform_data_intro_csv
    "temperature": data_city['main']['temp'],
TypeError: string indices must be integers
[2024-12-17T18:43:50.973+0000] {taskinstance.py:1138} INFO - Marking task as UP_FOR_RETRY. dag_id=weather_dag, task_id=transform_data, execution_date=20241217T184245, start_date=20241217T184350, end_date=20241217T184350
[2024-12-17T18:43:50.985+0000] {standard_task_runner.py:107} ERROR - Failed to execute job 97 for task transform_data (string indices must be integers; 14076)
[2024-12-17T18:43:51.013+0000] {local_task_job_runner.py:234} INFO - Task exited with return code 1
[2024-12-17T18:43:51.040+0000] {taskinstance.py:3280} INFO - 0 downstream tasks scheduled from follow-on schedule check
