[2024-12-17T14:28:06.115+0000] {taskinstance.py:1956} INFO - Dependencies all met for dep_context=non-requeueable deps ti=<TaskInstance: weather_dag.Extract_weather_data manual__2024-12-17T14:27:00.146947+00:00 [queued]>
[2024-12-17T14:28:06.124+0000] {taskinstance.py:1956} INFO - Dependencies all met for dep_context=requeueable deps ti=<TaskInstance: weather_dag.Extract_weather_data manual__2024-12-17T14:27:00.146947+00:00 [queued]>
[2024-12-17T14:28:06.124+0000] {taskinstance.py:2170} INFO - Starting attempt 2 of 3
[2024-12-17T14:28:06.136+0000] {taskinstance.py:2191} INFO - Executing <Task(PythonOperator): Extract_weather_data> on 2024-12-17 14:27:00.146947+00:00
[2024-12-17T14:28:06.142+0000] {standard_task_runner.py:60} INFO - Started process 3091 to run task
[2024-12-17T14:28:06.146+0000] {standard_task_runner.py:87} INFO - Running: ['***', 'tasks', 'run', 'weather_dag', 'Extract_weather_data', 'manual__2024-12-17T14:27:00.146947+00:00', '--job-id', '49', '--raw', '--subdir', 'DAGS_FOLDER/extract.py', '--cfg-path', '/tmp/tmpvg8nlyax']
[2024-12-17T14:28:06.147+0000] {standard_task_runner.py:88} INFO - Job 49: Subtask Extract_weather_data
[2024-12-17T14:28:06.159+0000] {warnings.py:109} WARNING - /home/***/.local/lib/python3.8/site-packages/***/settings.py:194: DeprecationWarning: The sql_alchemy_conn option in [core] has been moved to the sql_alchemy_conn option in [database] - the old setting has been used, but please update your config.
  SQL_ALCHEMY_CONN = conf.get("database", "SQL_ALCHEMY_CONN")

[2024-12-17T14:28:06.185+0000] {task_command.py:423} INFO - Running <TaskInstance: weather_dag.Extract_weather_data manual__2024-12-17T14:27:00.146947+00:00 [running]> on host 3b537f09ccb4
[2024-12-17T14:28:06.270+0000] {taskinstance.py:2480} INFO - Exporting env vars: AIRFLOW_CTX_DAG_EMAIL='thiernosidybah232@gmail.com' AIRFLOW_CTX_DAG_OWNER='***' AIRFLOW_CTX_DAG_ID='weather_dag' AIRFLOW_CTX_TASK_ID='Extract_weather_data' AIRFLOW_CTX_EXECUTION_DATE='2024-12-17T14:27:00.146947+00:00' AIRFLOW_CTX_TRY_NUMBER='2' AIRFLOW_CTX_DAG_RUN_ID='manual__2024-12-17T14:27:00.146947+00:00'
[2024-12-17T14:28:08.917+0000] {taskinstance.py:2698} ERROR - Task failed with exception
Traceback (most recent call last):
  File "/home/airflow/.local/lib/python3.8/site-packages/airflow/models/taskinstance.py", line 433, in _execute_task
    result = execute_callable(context=context, **execute_callable_kwargs)
  File "/home/airflow/.local/lib/python3.8/site-packages/airflow/operators/python.py", line 199, in execute
    return_value = self.execute_callable()
  File "/home/airflow/.local/lib/python3.8/site-packages/airflow/operators/python.py", line 216, in execute_callable
    return self.python_callable(*self.op_args, **self.op_kwargs)
  File "/opt/airflow/dags/extract.py", line 34, in extract_data
    json.dump(datas, file, indent=4)
  File "/usr/local/lib/python3.8/json/__init__.py", line 180, in dump
    fp.write(chunk)
TypeError: a bytes-like object is required, not 'str'
[2024-12-17T14:28:08.928+0000] {taskinstance.py:1138} INFO - Marking task as UP_FOR_RETRY. dag_id=weather_dag, task_id=Extract_weather_data, execution_date=20241217T142700, start_date=20241217T142806, end_date=20241217T142808
[2024-12-17T14:28:08.944+0000] {standard_task_runner.py:107} ERROR - Failed to execute job 49 for task Extract_weather_data (a bytes-like object is required, not 'str'; 3091)
[2024-12-17T14:28:08.966+0000] {local_task_job_runner.py:234} INFO - Task exited with return code 1
[2024-12-17T14:28:08.996+0000] {taskinstance.py:3280} INFO - 0 downstream tasks scheduled from follow-on schedule check
