[2024-12-17T18:55:37.617+0000] {taskinstance.py:1956} INFO - Dependencies all met for dep_context=non-requeueable deps ti=<TaskInstance: weather_dag.transform_data manual__2024-12-17T18:53:29.902421+00:00 [queued]>
[2024-12-17T18:55:37.626+0000] {taskinstance.py:1956} INFO - Dependencies all met for dep_context=requeueable deps ti=<TaskInstance: weather_dag.transform_data manual__2024-12-17T18:53:29.902421+00:00 [queued]>
[2024-12-17T18:55:37.627+0000] {taskinstance.py:2170} INFO - Starting attempt 3 of 3
[2024-12-17T18:55:37.639+0000] {taskinstance.py:2191} INFO - Executing <Task(PythonOperator): transform_data> on 2024-12-17 18:53:29.902421+00:00
[2024-12-17T18:55:37.645+0000] {standard_task_runner.py:60} INFO - Started process 14614 to run task
[2024-12-17T18:55:37.650+0000] {standard_task_runner.py:87} INFO - Running: ['***', 'tasks', 'run', 'weather_dag', 'transform_data', 'manual__2024-12-17T18:53:29.902421+00:00', '--job-id', '110', '--raw', '--subdir', 'DAGS_FOLDER/extract.py', '--cfg-path', '/tmp/tmpxrcf7ssf']
[2024-12-17T18:55:37.651+0000] {standard_task_runner.py:88} INFO - Job 110: Subtask transform_data
[2024-12-17T18:55:37.665+0000] {warnings.py:109} WARNING - /home/***/.local/lib/python3.8/site-packages/***/settings.py:194: DeprecationWarning: The sql_alchemy_conn option in [core] has been moved to the sql_alchemy_conn option in [database] - the old setting has been used, but please update your config.
  SQL_ALCHEMY_CONN = conf.get("database", "SQL_ALCHEMY_CONN")

[2024-12-17T18:55:37.700+0000] {task_command.py:423} INFO - Running <TaskInstance: weather_dag.transform_data manual__2024-12-17T18:53:29.902421+00:00 [running]> on host 3b537f09ccb4
[2024-12-17T18:55:37.760+0000] {taskinstance.py:2480} INFO - Exporting env vars: AIRFLOW_CTX_DAG_EMAIL='thiernosidybah232@gmail.com' AIRFLOW_CTX_DAG_OWNER='***' AIRFLOW_CTX_DAG_ID='weather_dag' AIRFLOW_CTX_TASK_ID='transform_data' AIRFLOW_CTX_EXECUTION_DATE='2024-12-17T18:53:29.902421+00:00' AIRFLOW_CTX_TRY_NUMBER='3' AIRFLOW_CTX_DAG_RUN_ID='manual__2024-12-17T18:53:29.902421+00:00'
[2024-12-17T18:55:37.761+0000] {taskinstance.py:2698} ERROR - Task failed with exception
Traceback (most recent call last):
  File "/home/airflow/.local/lib/python3.8/site-packages/airflow/models/taskinstance.py", line 433, in _execute_task
    result = execute_callable(context=context, **execute_callable_kwargs)
  File "/home/airflow/.local/lib/python3.8/site-packages/airflow/operators/python.py", line 199, in execute
    return_value = self.execute_callable()
  File "/home/airflow/.local/lib/python3.8/site-packages/airflow/operators/python.py", line 216, in execute_callable
    return self.python_callable(*self.op_args, **self.op_kwargs)
  File "/opt/airflow/dags/extract.py", line 56, in transform_data_intro_csv
    data_temp = json.load(file)
  File "/usr/local/lib/python3.8/json/__init__.py", line 293, in load
    return loads(fp.read(),
  File "/usr/local/lib/python3.8/json/__init__.py", line 357, in loads
    return _default_decoder.decode(s)
  File "/usr/local/lib/python3.8/json/decoder.py", line 337, in decode
    obj, end = self.raw_decode(s, idx=_w(s, 0).end())
  File "/usr/local/lib/python3.8/json/decoder.py", line 355, in raw_decode
    raise JSONDecodeError("Expecting value", s, err.value) from None
json.decoder.JSONDecodeError: Expecting value: line 1 column 1 (char 0)
[2024-12-17T18:55:37.769+0000] {taskinstance.py:1138} INFO - Marking task as FAILED. dag_id=weather_dag, task_id=transform_data, execution_date=20241217T185329, start_date=20241217T185537, end_date=20241217T185537
[2024-12-17T18:55:37.781+0000] {standard_task_runner.py:107} ERROR - Failed to execute job 110 for task transform_data (Expecting value: line 1 column 1 (char 0); 14614)
[2024-12-17T18:55:37.820+0000] {local_task_job_runner.py:234} INFO - Task exited with return code 1
[2024-12-17T18:55:37.845+0000] {taskinstance.py:3280} INFO - 0 downstream tasks scheduled from follow-on schedule check
